Workbook
Name Area_ha: Assumptions!$B$14
Name CR_a: Assumptions!$B$18
Name CR_b: Assumptions!$B$19
Name CR_c: Assumptions!$B$20
Name Stumpage: Assumptions!$B$23
Name PriceGrowth: Assumptions!$B$24
Name RegenCost: Assumptions!$B$25
Name MgmtCost: Assumptions!$B$26
Name PurchasePrice: Assumptions!$B$28
Name AcqCostPct: Assumptions!$B$29
Name DiscRate: Assumptions!$B$30
Name Hurdle: Assumptions!$B$31
Name HoldYears: Assumptions!$B$32
Name DispCostPct: Assumptions!$B$36
Name EvenFlowTol: Assumptions!$B$33
Name MinHarvestAge: Assumptions!$B$34
Name CarbonOn: Assumptions!$B$48
Name CarbonPrice: Assumptions!$B$49
Name CarbonRate: Assumptions!$B$50
Name CarbonArea: Assumptions!$B$51
Name RotationAge: Growth_Rotation!$B$9
Name FaustmannLEV: Growth_Rotation!$C$9
Name ExitInventoryValue: Harvest_Schedule!$F$208
Name ClosingInventory: Harvest_Schedule!$D$208
Name OpeningInventory: Harvest_Schedule!$E$18
Name HarvestVolumes: Harvest_Schedule!$B$22:$B$51
Name HarvestAreas: Harvest_Schedule!$C$22:$C$51
Name ExitPrice: Cash_Flows!$B$6
Name VolAtRotation: Cash_Flows!$B$7
Name LEVT_Exit: Cash_Flows!$B$8
Name TerminalValue: Cash_Flows!$B$10
Name ProjectNPV: Cash_Flows!$B$46
Name ProjectIRR: Cash_Flows!$B$47
Name ProjectMOIC: Cash_Flows!$B$50
Name BreakevenPrice: Cash_Flows!$B$52
Name Recommendation: Cash_Flows!$B$55

Sheet Cover
B2: Project Aspen
B3: Timberland acquisition analysis: 20,000 ha boreal tract, Alberta
B4: HYPOTHETICAL TRACT, FOR PORTFOLIO PURPOSES ONLY. NOT INVESTMENT ADVICE.
B5: Prepared by Harsit Baral · all figures in real CAD
B7: Headline results
B8: Every figure below is a live link to the sheet that computes it.
B9: Measure | C9: Value | D9: Computed on
B10: Asking price | C10: =PurchasePrice | D10: Assumptions
B11: Net present value at the hurdle | C11: =ProjectNPV | D11: Cash_Flows
B12: Project IRR | C12: =ProjectIRR | D12: Cash_Flows
B13: Hurdle rate | C13: =Hurdle | D13: Assumptions
B14: Multiple on invested capital | C14: =ProjectMOIC | D14: Cash_Flows
B15: Breakeven purchase price | C15: =BreakevenPrice | D15: Cash_Flows
B16: Faustmann rotation age | C16: =RotationAge | D16: Growth_Rotation
B17: Land expectation value | C17: =FaustmannLEV | D17: Growth_Rotation
B18: Sustainable annual cut | C18: =AVERAGE(HarvestVolumes) | D18: Harvest_Schedule
B19: Recommendation | C19: =Recommendation | D19: Cash_Flows
B21: Risk and portfolio fit
B22: Measure | C22: Value | D22: Basis
B23: Probability of missing the hurdle | C23: 0.0956 | D23: 10,000 simulated paths, seed 42
B24: IRR range, 5th to 95th percentile | C24: 5.6% to 10.6% | D24: Monte_Carlo
B25: Value of harvest timing flexibility | C25: 3526108 | D25: A real option created by mean-reverting prices
B26: Expected cost of fire and pests | C26: 1124144.4 | D26: Measured against identical price paths with no disturbance
B27: Timber proxy correlation to the S&P/TSX | C27: 0.47380403 | D27: Listed REITs are equities first, an upper bound on true correlation
B28: Proxies with a significant inflation beta | C28: 0 of 8 | D28: At the 10% level; see Market_Analysis
B31: Contents
B32: Sheet | D32: What it contains
B33: Cover | D33: Title, contents and headline results
B34: Assumptions | D34: Every input, with its unit and source
B35: Growth_Rotation | D35: Yield curve and the three rotation criteria
B36: Harvest_Schedule | D36: Age classes, annual cut and the year-30 forest
B37: Cash_Flows | D37: 30-year DCF, NPV, IRR, MOIC and breakeven
B38: Sensitivity | D38: Two-way IRR grids
B39: Monte_Carlo | D39: 10,000-path risk simulation
B40: Market_Analysis | D40: Correlation and inflation evidence
B42: How to read this workbook
B43: Blue text on yellow | D43: A hard input. These are the only numbers typed in; change one and everything downstream moves.
B44: Black text | D44: A formula calculated on that sheet. Click it to see the logic.
B45: Green text | D45: A link to another sheet, or a value produced by the Python model where Excel cannot reproduce the calculation.
B47: Note: this file is generated by openpyxl, which writes formulas but does not calculate them. Formula cells appear blank until Excel or LibreOffice opens the workbook and recalculates. Press Ctrl+Alt+F9 to force a full rebuild.

Sheet Assumptions
A1: Assumptions
A2: One row per input. Blue on yellow cells are the only hard-coded numbers in this workbook.
A3: HYPOTHETICAL TRACT, FOR PORTFOLIO PURPOSES ONLY. NOT INVESTMENT ADVICE.
A5: Parameter | B5: Value | C5: Unit | D5: Source | E5: Note
A6: Project identity
A7: Project name | B7: Project Aspen | C7: text | D7: Illustrative assumption | E7: Internal code name for the hypothetical transaction.
A8: Disclaimer | B8: Hypothetical, for portfolio purposes only | C8: text | D8: Illustrative assumption | E8: Printed on every deliverable so no reader mistakes this for a live deal.
A9: Analyst | B9: Harsit Baral | C9: text | D9: Illustrative assumption | E9: Author of the analysis.
A10: Base currency | B10: CAD | C10: text | D10: Illustrative assumption | E10: All dollar figures are real (constant) Canadian dollars unless stated otherwise.
A11: Valuation basis | B11: Real (constant dollars) | C11: text | D11: Illustrative assumption | E11: Real cash flows discounted at a real rate; inflation nets out of both sides.
A12: Tract: physical description
A13: Location | B13: Boreal mixedwood, north-central Alberta | C13: text | D13: Illustrative assumption | E13: Hypothetical location chosen to make the growth and risk assumptions plausible.
A14: Area ha | B14: 20000 | C14: hectares | D14: Illustrative assumption | E14: Total productive freehold area; assumed fully operable with road access.
A15: Age class distribution ha | B15: see Harvest_Schedule | C15: hectares per 10-year age class | D15: Illustrative assumption | E15: Uneven and skewed to mature classes, typical of a tract with limited recent harvesting; sums to 20,000 ha.
A16: Species mix | B16: White spruce / trembling aspen mixedwood | C16: text | D16: Illustrative assumption | E16: Drives the choice of a single aggregate yield curve rather than species-specific curves.
A17: Growth curve (Chapman-Richards)
A18: Chapman richards a | B18: 350 | C18: m3 per hectare | D18: Illustrative assumption | E18: Asymptotic maximum merchantable volume the stand approaches at old age.
A19: Chapman richards b | B19: 0.03 | C19: per year | D19: Illustrative assumption | E19: Growth rate parameter; larger b means the stand approaches the asymptote sooner.
A20: Chapman richards c | B20: 3 | C20: dimensionless | D20: Illustrative assumption | E20: Shape parameter; c > 1 produces the S-curve with slow juvenile growth.
A21: Max modelled age | B21: 150 | C21: years | D21: Illustrative assumption | E21: Upper bound for the age axis in the rotation search and the Excel growth table.
A22: Prices and operating costs
A23: Net stumpage price | B23: 48 | C23: CAD per m3 | D23: Illustrative assumption | E23: Delivered log price net of harvest, haul and road costs, i.e. what accrues to the landowner.
A24: Real price growth | B24: 0.005 | C24: fraction per year | D24: Illustrative assumption | E24: 0.5% real annual stumpage appreciation; deliberately conservative versus long-run commodity trends.
A25: Regeneration cost | B25: 400 | C25: CAD per hectare | D25: Illustrative assumption | E25: Site preparation, planting and early tending, charged in the year a stand is harvested.
A26: Management cost | B26: 8 | C26: CAD per hectare per year | D26: Illustrative assumption | E26: Extensive management: property tax, roads, inventory, protection and overhead.
A27: Transaction, discounting and harvest rules
A28: Purchase price | B28: 92000000 | C28: CAD | D28: Illustrative assumption | E28: Assumed all-cash asking price for the tract (CAD 4,600 per hectare); the model tests whether it is justified.
A29: Acquisition cost pct | B29: 0.01 | C29: fraction of purchase price | D29: Illustrative assumption | E29: Legal, survey, timber cruise and closing costs paid at year 0.
A30: Real discount rate | B30: 0.06 | C30: fraction per year | D30: Illustrative assumption | E30: 6.0% real unlevered discount rate for a core private timberland asset.
A31: Hurdle rate | B31: 0.06 | C31: fraction per year | D31: Illustrative assumption | E31: Set equal to the discount rate so that NPV > 0 and IRR > hurdle give the same buy signal.
A32: Holding period years | B32: 30 | C32: years | D32: Illustrative assumption | E32: Fund-style 30-year hold, after which the tract is assumed sold.
A33: Even flow tolerance | B33: 0.15 | C33: fraction of mean annual harvest | D33: Illustrative assumption | E33: Annual harvest must stay within +/-15% of the 30-year average, mimicking a mill supply agreement.
A34: Min harvest age | B34: 20 | C34: years | D34: Illustrative assumption | E34: Floor on merchantability: stands younger than this are never cut, even to defend the even-flow target.
A35: Min ending inventory multiple | B35: 1 | C35: multiple of regulated growing stock | D35: Illustrative assumption | E35: Standing volume at exit must be at least the growing stock of a fully regulated forest, so the buyer inherits a going concern rather than cut-over land.
A36: Disposition cost pct | B36: 0.015 | C36: fraction of terminal value | D36: Illustrative assumption | E36: Brokerage and closing costs deducted from the exit proceeds.
A37: Terminal value method | B37: Bare land expectation value plus discounted value of standing inventory | C37: text | D37: Illustrative assumption | E37: Exit priced as a rational buyer would: perpetual land value plus the timber standing on it at year 30.
A38: Monte Carlo risk parameters
A39: N simulations | B39: 10000 | C39: paths | D39: Illustrative assumption | E39: Enough paths that the reported percentiles are stable to roughly 0.1 percentage points of IRR.
A40: Random seed | B40: 42 | C40: integer | D40: Illustrative assumption | E40: Fixed so every rerun of run_all.py reproduces the published numbers exactly.
A41: Price volatility | B41: 0.22 | C41: annual standard deviation of log price | D41: Illustrative assumption | E41: 22% annual volatility, in the range historically shown by North American sawlog and lumber prices.
...

Sheet Growth_Rotation
A1: Growth and optimal rotation
A2: Chapman-Richards yield curve. Every cell below is a formula reading the Assumptions sheet: change an input there and the optimum moves.
A3: HYPOTHETICAL TRACT, FOR PORTFOLIO PURPOSES ONLY. NOT INVESTMENT ADVICE.
A5: Rotation criteria
A6: Criterion | B6: Age (yrs) | C6: Value | D6: What it maximises
A7: Maximum mean annual increment | B7: =INDEX($A$12:$A$161,MATCH(MAX($C$12:$C$161),$C$12:$C$161,0)) | C7: =MAX($C$12:$C$161) | D7: Volume per year, V(T)/T. Ignores money entirely.
A8: Single rotation NPV (Fisher) | B8: =INDEX($A$12:$A$161,MATCH(MAX($F$12:$F$161),$F$12:$F$161,0)) | C8: =MAX($F$12:$F$161) | D8: Discounted profit of one rotation. Counts interest, not land.
A9: Faustmann (land expectation value) | B9: =INDEX($A$12:$A$161,MATCH(MAX($E$12:$E$161),$E$12:$E$161,0)) | C9: =MAX($E$12:$E$161) | D9: Value of the bare land in perpetuity. Counts the opportunity cost of delaying every future rotation, so it is the shortest.
A10: Rotation used in the cash flow model | B10: =B9
A11: Age (yrs) | B11: Volume V(T) (m³/ha) | C11: MAI (m³/ha/yr) | D11: CAI (m³/ha/yr) | E11: LEV ($/ha) | F11: Single-rotation NPV ($/ha)
A12: 1 | B12: =CR_a*(1-EXP(-CR_b*$A12))^CR_c | C12: =$B12/$A12 | D12: =CR_a*CR_b*CR_c*(1-EXP(-CR_b*$A12))^(CR_c-1)*EXP(-CR_b*$A12) | E12: =IF($A12<2,"",(Stumpage*$B12-RegenCost*(1+DiscRate)^$A12)/((1+DiscRate)^$A12-1)-MgmtCost/DiscRate) | F12: =Stumpage*$B12/(1+DiscRate)^$A12-RegenCost-MgmtCost*(1-(1+DiscRate)^-$A12)/DiscRate
A13: 2 | B13: =CR_a*(1-EXP(-CR_b*$A13))^CR_c | C13: =$B13/$A13 | D13: =CR_a*CR_b*CR_c*(1-EXP(-CR_b*$A13))^(CR_c-1)*EXP(-CR_b*$A13) | E13: =IF($A13<2,"",(Stumpage*$B13-RegenCost*(1+DiscRate)^$A13)/((1+DiscRate)^$A13-1)-MgmtCost/DiscRate) | F13: =Stumpage*$B13/(1+DiscRate)^$A13-RegenCost-MgmtCost*(1-(1+DiscRate)^-$A13)/DiscRate
A14: 3 | B14: =CR_a*(1-EXP(-CR_b*$A14))^CR_c | C14: =$B14/$A14 | D14: =CR_a*CR_b*CR_c*(1-EXP(-CR_b*$A14))^(CR_c-1)*EXP(-CR_b*$A14) | E14: =IF($A14<2,"",(Stumpage*$B14-RegenCost*(1+DiscRate)^$A14)/((1+DiscRate)^$A14-1)-MgmtCost/DiscRate) | F14: =Stumpage*$B14/(1+DiscRate)^$A14-RegenCost-MgmtCost*(1-(1+DiscRate)^-$A14)/DiscRate
A15: 4 | B15: =CR_a*(1-EXP(-CR_b*$A15))^CR_c | C15: =$B15/$A15 | D15: =CR_a*CR_b*CR_c*(1-EXP(-CR_b*$A15))^(CR_c-1)*EXP(-CR_b*$A15) | E15: =IF($A15<2,"",(Stumpage*$B15-RegenCost*(1+DiscRate)^$A15)/((1+DiscRate)^$A15-1)-MgmtCost/DiscRate) | F15: =Stumpage*$B15/(1+DiscRate)^$A15-RegenCost-MgmtCost*(1-(1+DiscRate)^-$A15)/DiscRate
A16: 5 | B16: =CR_a*(1-EXP(-CR_b*$A16))^CR_c | C16: =$B16/$A16 | D16: =CR_a*CR_b*CR_c*(1-EXP(-CR_b*$A16))^(CR_c-1)*EXP(-CR_b*$A16) | E16: =IF($A16<2,"",(Stumpage*$B16-RegenCost*(1+DiscRate)^$A16)/((1+DiscRate)^$A16-1)-MgmtCost/DiscRate) | F16: =Stumpage*$B16/(1+DiscRate)^$A16-RegenCost-MgmtCost*(1-(1+DiscRate)^-$A16)/DiscRate
A17: 6 | B17: =CR_a*(1-EXP(-CR_b*$A17))^CR_c | C17: =$B17/$A17 | D17: =CR_a*CR_b*CR_c*(1-EXP(-CR_b*$A17))^(CR_c-1)*EXP(-CR_b*$A17) | E17: =IF($A17<2,"",(Stumpage*$B17-RegenCost*(1+DiscRate)^$A17)/((1+DiscRate)^$A17-1)-MgmtCost/DiscRate) | F17: =Stumpage*$B17/(1+DiscRate)^$A17-RegenCost-MgmtCost*(1-(1+DiscRate)^-$A17)/DiscRate
A18: 7 | B18: =CR_a*(1-EXP(-CR_b*$A18))^CR_c | C18: =$B18/$A18 | D18: =CR_a*CR_b*CR_c*(1-EXP(-CR_b*$A18))^(CR_c-1)*EXP(-CR_b*$A18) | E18: =IF($A18<2,"",(Stumpage*$B18-RegenCost*(1+DiscRate)^$A18)/((1+DiscRate)^$A18-1)-MgmtCost/DiscRate) | F18: =Stumpage*$B18/(1+DiscRate)^$A18-RegenCost-MgmtCost*(1-(1+DiscRate)^-$A18)/DiscRate
A19: 8 | B19: =CR_a*(1-EXP(-CR_b*$A19))^CR_c | C19: =$B19/$A19 | D19: =CR_a*CR_b*CR_c*(1-EXP(-CR_b*$A19))^(CR_c-1)*EXP(-CR_b*$A19) | E19: =IF($A19<2,"",(Stumpage*$B19-RegenCost*(1+DiscRate)^$A19)/((1+DiscRate)^$A19-1)-MgmtCost/DiscRate) | F19: =Stumpage*$B19/(1+DiscRate)^$A19-RegenCost-MgmtCost*(1-(1+DiscRate)^-$A19)/DiscRate
A20: 9 | B20: =CR_a*(1-EXP(-CR_b*$A20))^CR_c | C20: =$B20/$A20 | D20: =CR_a*CR_b*CR_c*(1-EXP(-CR_b*$A20))^(CR_c-1)*EXP(-CR_b*$A20) | E20: =IF($A20<2,"",(Stumpage*$B20-RegenCost*(1+DiscRate)^$A20)/((1+DiscRate)^$A20-1)-MgmtCost/DiscRate) | F20: =Stumpage*$B20/(1+DiscRate)^$A20-RegenCost-MgmtCost*(1-(1+DiscRate)^-$A20)/DiscRate
A21: 10 | B21: =CR_a*(1-EXP(-CR_b*$A21))^CR_c | C21: =$B21/$A21 | D21: =CR_a*CR_b*CR_c*(1-EXP(-CR_b*$A21))^(CR_c-1)*EXP(-CR_b*$A21) | E21: =IF($A21<2,"",(Stumpage*$B21-RegenCost*(1+DiscRate)^$A21)/((1+DiscRate)^$A21-1)-MgmtCost/DiscRate) | F21: =Stumpage*$B21/(1+DiscRate)^$A21-RegenCost-MgmtCost*(1-(1+DiscRate)^-$A21)/DiscRate
A22: 11 | B22: =CR_a*(1-EXP(-CR_b*$A22))^CR_c | C22: =$B22/$A22 | D22: =CR_a*CR_b*CR_c*(1-EXP(-CR_b*$A22))^(CR_c-1)*EXP(-CR_b*$A22) | E22: =IF($A22<2,"",(Stumpage*$B22-RegenCost*(1+DiscRate)^$A22)/((1+DiscRate)^$A22-1)-MgmtCost/DiscRate) | F22: =Stumpage*$B22/(1+DiscRate)^$A22-RegenCost-MgmtCost*(1-(1+DiscRate)^-$A22)/DiscRate
A23: 12 | B23: =CR_a*(1-EXP(-CR_b*$A23))^CR_c | C23: =$B23/$A23 | D23: =CR_a*CR_b*CR_c*(1-EXP(-CR_b*$A23))^(CR_c-1)*EXP(-CR_b*$A23) | E23: =IF($A23<2,"",(Stumpage*$B23-RegenCost*(1+DiscRate)^$A23)/((1+DiscRate)^$A23-1)-MgmtCost/DiscRate) | F23: =Stumpage*$B23/(1+DiscRate)^$A23-RegenCost-MgmtCost*(1-(1+DiscRate)^-$A23)/DiscRate
... A161: 150 | B161: =CR_a*(1-EXP(-CR_b*$A161))^CR_c | C161: =$B161/$A161 | D161: =CR_a*CR_b*CR_c*(1-EXP(-CR_b*$A161))^(CR_c-1)*EXP(-CR_b*$A161) | E161: =IF($A161<2,"",(Stumpage*$B161-RegenCost*(1+DiscRate)^$A161)/((1+DiscRate)^$A161-1)-MgmtCost/DiscRate) | F161: =Stumpage*$B161/(1+DiscRate)^$A161-RegenCost-MgmtCost*(1-(1+DiscRate)^-$A161)/DiscRate

Sheet Harvest_Schedule
A1: Harvest schedule and age-class structure
A2: Hectares by age come from the cohort simulation in src/dcf.py. Volumes and values beside them are live formulas.
A3: HYPOTHETICAL TRACT, FOR PORTFOLIO PURPOSES ONLY. NOT INVESTMENT ADVICE.
A5: Opening age-class distribution (acquisition)
A6: Hectares are spread evenly across the ten single years inside each class. Because the yield curve is convex, the average volume across those ten ages is not the volume at the midpoint age, so column D averages the live growth table rather than evaluating the curve once.
A7: Age class | B7: Hectares | C7: Ages included | D7: Average volume per ha (m³) | E7: Standing volume (m³)
A8: 0-9 | B8: 900 | C8: 0-9 | D8: =SUM(Growth_Rotation!$B$12:$B$20)/10 | E8: =$B8*$D8
A9: 10-19 | B9: 1100 | C9: 10-19 | D9: =SUM(Growth_Rotation!$B$21:$B$30)/10 | E9: =$B9*$D9
A10: 20-29 | B10: 1400 | C10: 20-29 | D10: =SUM(Growth_Rotation!$B$31:$B$40)/10 | E10: =$B10*$D10
A11: 30-39 | B11: 1700 | C11: 30-39 | D11: =SUM(Growth_Rotation!$B$41:$B$50)/10 | E11: =$B11*$D11
A12: 40-49 | B12: 2000 | C12: 40-49 | D12: =SUM(Growth_Rotation!$B$51:$B$60)/10 | E12: =$B12*$D12
A13: 50-59 | B13: 2600 | C13: 50-59 | D13: =SUM(Growth_Rotation!$B$61:$B$70)/10 | E13: =$B13*$D13
A14: 60-69 | B14: 3400 | C14: 60-69 | D14: =SUM(Growth_Rotation!$B$71:$B$80)/10 | E14: =$B14*$D14
A15: 70-79 | B15: 3200 | C15: 70-79 | D15: =SUM(Growth_Rotation!$B$81:$B$90)/10 | E15: =$B15*$D15
A16: 80-89 | B16: 2300 | C16: 80-89 | D16: =SUM(Growth_Rotation!$B$91:$B$100)/10 | E16: =$B16*$D16
A17: 90-99 | B17: 1400 | C17: 90-99 | D17: =SUM(Growth_Rotation!$B$101:$B$110)/10 | E17: =$B17*$D17
A18: Total | B18: =SUM(B8:B17) | E18: =SUM(E8:E17) | F18: ← opening inventory, m³
A20: Annual harvest (values from the cohort simulation)
A21: Year | B21: Harvest volume (m³) | C21: Area cut (ha) | D21: Lower even-flow bound | E21: Upper even-flow bound
A22: 1 | B22: 155918.57 | C22: 522.77806 | D22: =AVERAGE($B$22:$B$51)*(1-EvenFlowTol) | E22: =AVERAGE($B$22:$B$51)*(1+EvenFlowTol)
A23: 2 | B23: 155918.57 | C23: 530.21934 | D23: =AVERAGE($B$22:$B$51)*(1-EvenFlowTol) | E23: =AVERAGE($B$22:$B$51)*(1+EvenFlowTol)
A24: 3 | B24: 155918.57 | C24: 538.34652 | D24: =AVERAGE($B$22:$B$51)*(1-EvenFlowTol) | E24: =AVERAGE($B$22:$B$51)*(1+EvenFlowTol)
A25: 4 | B25: 155918.57 | C25: 543.76986 | D25: =AVERAGE($B$22:$B$51)*(1-EvenFlowTol) | E25: =AVERAGE($B$22:$B$51)*(1+EvenFlowTol)
A26: 5 | B26: 155918.57 | C26: 548.5675 | D26: =AVERAGE($B$22:$B$51)*(1-EvenFlowTol) | E26: =AVERAGE($B$22:$B$51)*(1+EvenFlowTol)
A27: 6 | B27: 155918.57 | C27: 553.40532 | D27: =AVERAGE($B$22:$B$51)*(1-EvenFlowTol) | E27: =AVERAGE($B$22:$B$51)*(1+EvenFlowTol)
A28: 7 | B28: 155918.57 | C28: 559.23254 | D28: =AVERAGE($B$22:$B$51)*(1-EvenFlowTol) | E28: =AVERAGE($B$22:$B$51)*(1+EvenFlowTol)
A29: 8 | B29: 155918.57 | C29: 562.79367 | D29: =AVERAGE($B$22:$B$51)*(1-EvenFlowTol) | E29: =AVERAGE($B$22:$B$51)*(1+EvenFlowTol)
A30: 9 | B30: 155918.57 | C30: 566.26365 | D30: =AVERAGE($B$22:$B$51)*(1-EvenFlowTol) | E30: =AVERAGE($B$22:$B$51)*(1+EvenFlowTol)
A31: 10 | B31: 155918.57 | C31: 569.62258 | D31: =AVERAGE($B$22:$B$51)*(1-EvenFlowTol) | E31: =AVERAGE($B$22:$B$51)*(1+EvenFlowTol)
A32: 11 | B32: 155918.57 | C32: 572.99911 | D32: =AVERAGE($B$22:$B$51)*(1-EvenFlowTol) | E32: =AVERAGE($B$22:$B$51)*(1+EvenFlowTol)
A33: 12 | B33: 155918.57 | C33: 576.54421 | D33: =AVERAGE($B$22:$B$51)*(1-EvenFlowTol) | E33: =AVERAGE($B$22:$B$51)*(1+EvenFlowTol)
... A51: 30 | B51: 155918.57 | C51: 1034.6743 | D51: =AVERAGE($B$22:$B$51)*(1-EvenFlowTol) | E51: =AVERAGE($B$22:$B$51)*(1+EvenFlowTol)
A53: Even-flow check | B53: =IF(AND(MIN(B22:B51)>=D22-1,MAX(B22:B51)<=E22+1),"PASS: every year inside the band","FAIL")
A55: Age distribution at exit (year 30): this is the forest the next buyer acquires
A56: Age (yrs) | B56: Hectares | C56: Volume per ha (m³) | D56: Standing volume (m³) | E56: Exit value per ha ($) | F56: Exit value ($)
A57: 0 | B57: 1034.6743 | C57: =CR_a*(1-EXP(-CR_b*$A57))^CR_c | D57: =$B57*$C57 | E57: =IF($A57>=RotationAge,ExitPrice*$C57+LEVT_Exit,(ExitPrice*VolAtRotation+LEVT_Exit)/(1+DiscRate)^(RotationAge-$A57)) | F57: =$B57*$E57
A58: 1 | B58: 876.74127 | C58: =CR_a*(1-EXP(-CR_b*$A58))^CR_c | D58: =$B58*$C58 | E58: =IF($A58>=RotationAge,ExitPrice*$C58+LEVT_Exit,(ExitPrice*VolAtRotation+LEVT_Exit)/(1+DiscRate)^(RotationAge-$A58)) | F58: =$B58*$E58
A59: 2 | B59: 793.49331 | C59: =CR_a*(1-EXP(-CR_b*$A59))^CR_c | D59: =$B59*$C59 | E59: =IF($A59>=RotationAge,ExitPrice*$C59+LEVT_Exit,(ExitPrice*VolAtRotation+LEVT_Exit)/(1+DiscRate)^(RotationAge-$A59)) | F59: =$B59*$E59
A60: 3 | B60: 743.77756 | C60: =CR_a*(1-EXP(-CR_b*$A60))^CR_c | D60: =$B60*$C60 | E60: =IF($A60>=RotationAge,ExitPrice*$C60+LEVT_Exit,(ExitPrice*VolAtRotation+LEVT_Exit)/(1+DiscRate)^(RotationAge-$A60)) | F60: =$B60*$E60
A61: 4 | B61: 706.97812 | C61: =CR_a*(1-EXP(-CR_b*$A61))^CR_c | D61: =$B61*$C61 | E61: =IF($A61>=RotationAge,ExitPrice*$C61+LEVT_Exit,(ExitPrice*VolAtRotation+LEVT_Exit)/(1+DiscRate)^(RotationAge-$A61)) | F61: =$B61*$E61
...

Sheet Cash_Flows
A1: Acquisition cash flows
A2: Real Canadian dollars. Every cell is a formula: NPV and IRR use Excel's own functions over the net cash flow column.
A3: HYPOTHETICAL TRACT, FOR PORTFOLIO PURPOSES ONLY. NOT INVESTMENT ADVICE.
A5: Exit pricing inputs
A6: Stumpage price at exit | B6: =Stumpage*(1+PriceGrowth)^HoldYears | C6: Real price escalated over the hold
A7: Volume per ha at the rotation age | B7: =CR_a*(1-EXP(-CR_b*RotationAge))^CR_c | C7: Chapman-Richards evaluated at the Faustmann age
A8: Land expectation value at exit prices, before management | B8: =(ExitPrice*VolAtRotation-RegenCost*(1+DiscRate)^RotationAge)/((1+DiscRate)^RotationAge-1) | C8: LEV recomputed at the year-30 price
A9: Gross exit value of land and timber | B9: =ExitInventoryValue-MgmtCost/DiscRate*Area_ha | C9: Summed from the year-30 age table on Harvest_Schedule
A10: Net exit proceeds after disposition costs | B10: =B9*(1-DispCostPct)
A12: Year | B12: Harvest volume (m³) | C12: Area cut (ha) | D12: Stumpage ($/m³) | E12: Harvest revenue | F12: Carbon revenue | G12: Regeneration | H12: Management | I12: Acquisition | J12: Terminal value | K12: Net cash flow | L12: Discount factor | M12: PV of cash flow | N12: Cumulative PV
A13: 0 | B13: 0 | C13: 0 | D13: =Stumpage*(1+PriceGrowth)^$A13 | E13: =$B13*$D13 | F13: =IF(AND(CarbonOn,$A13>0),Area_ha*CarbonArea*CarbonRate*CarbonPrice,0) | G13: =-$C13*RegenCost | H13: =IF($A13>0,-Area_ha*MgmtCost,0) | I13: =IF($A13=0,-PurchasePrice*(1+AcqCostPct),0) | J13: =IF($A13=HoldYears,TerminalValue,0) | K13: =SUM($E13:$J13) | L13: =1/(1+DiscRate)^$A13 | M13: =$K13*$L13 | N13: =SUM($M$13:$M13)
A14: 1 | B14: =Harvest_Schedule!$B$22 | C14: =Harvest_Schedule!$C$22 | D14: =Stumpage*(1+PriceGrowth)^$A14 | E14: =$B14*$D14 | F14: =IF(AND(CarbonOn,$A14>0),Area_ha*CarbonArea*CarbonRate*CarbonPrice,0) | G14: =-$C14*RegenCost | H14: =IF($A14>0,-Area_ha*MgmtCost,0) | I14: =IF($A14=0,-PurchasePrice*(1+AcqCostPct),0) | J14: =IF($A14=HoldYears,TerminalValue,0) | K14: =SUM($E14:$J14) | L14: =1/(1+DiscRate)^$A14 | M14: =$K14*$L14 | N14: =SUM($M$13:$M14)
A15: 2 | B15: =Harvest_Schedule!$B$23 | C15: =Harvest_Schedule!$C$23 | D15: =Stumpage*(1+PriceGrowth)^$A15 | E15: =$B15*$D15 | F15: =IF(AND(CarbonOn,$A15>0),Area_ha*CarbonArea*CarbonRate*CarbonPrice,0) | G15: =-$C15*RegenCost | H15: =IF($A15>0,-Area_ha*MgmtCost,0) | I15: =IF($A15=0,-PurchasePrice*(1+AcqCostPct),0) | J15: =IF($A15=HoldYears,TerminalValue,0) | K15: =SUM($E15:$J15) | L15: =1/(1+DiscRate)^$A15 | M15: =$K15*$L15 | N15: =SUM($M$13:$M15)
A16: 3 | B16: =Harvest_Schedule!$B$24 | C16: =Harvest_Schedule!$C$24 | D16: =Stumpage*(1+PriceGrowth)^$A16 | E16: =$B16*$D16 | F16: =IF(AND(CarbonOn,$A16>0),Area_ha*CarbonArea*CarbonRate*CarbonPrice,0) | G16: =-$C16*RegenCost | H16: =IF($A16>0,-Area_ha*MgmtCost,0) | I16: =IF($A16=0,-PurchasePrice*(1+AcqCostPct),0) | J16: =IF($A16=HoldYears,TerminalValue,0) | K16: =SUM($E16:$J16) | L16: =1/(1+DiscRate)^$A16 | M16: =$K16*$L16 | N16: =SUM($M$13:$M16)
A17: 4 | B17: =Harvest_Schedule!$B$25 | C17: =Harvest_Schedule!$C$25 | D17: =Stumpage*(1+PriceGrowth)^$A17 | E17: =$B17*$D17 | F17: =IF(AND(CarbonOn,$A17>0),Area_ha*CarbonArea*CarbonRate*CarbonPrice,0) | G17: =-$C17*RegenCost | H17: =IF($A17>0,-Area_ha*MgmtCost,0) | I17: =IF($A17=0,-PurchasePrice*(1+AcqCostPct),0) | J17: =IF($A17=HoldYears,TerminalValue,0) | K17: =SUM($E17:$J17) | L17: =1/(1+DiscRate)^$A17 | M17: =$K17*$L17 | N17: =SUM($M$13:$M17)
A18: 5 | B18: =Harvest_Schedule!$B$26 | C18: =Harvest_Schedule!$C$26 | D18: =Stumpage*(1+PriceGrowth)^$A18 | E18: =$B18*$D18 | F18: =IF(AND(CarbonOn,$A18>0),Area_ha*CarbonArea*CarbonRate*CarbonPrice,0) | G18: =-$C18*RegenCost | H18: =IF($A18>0,-Area_ha*MgmtCost,0) | I18: =IF($A18=0,-PurchasePrice*(1+AcqCostPct),0) | J18: =IF($A18=HoldYears,TerminalValue,0) | K18: =SUM($E18:$J18) | L18: =1/(1+DiscRate)^$A18 | M18: =$K18*$L18 | N18: =SUM($M$13:$M18)
A19: 6 | B19: =Harvest_Schedule!$B$27 | C19: =Harvest_Schedule!$C$27 | D19: =Stumpage*(1+PriceGrowth)^$A19 | E19: =$B19*$D19 | F19: =IF(AND(CarbonOn,$A19>0),Area_ha*CarbonArea*CarbonRate*CarbonPrice,0) | G19: =-$C19*RegenCost | H19: =IF($A19>0,-Area_ha*MgmtCost,0) | I19: =IF($A19=0,-PurchasePrice*(1+AcqCostPct),0) | J19: =IF($A19=HoldYears,TerminalValue,0) | K19: =SUM($E19:$J19) | L19: =1/(1+DiscRate)^$A19 | M19: =$K19*$L19 | N19: =SUM($M$13:$M19)
A20: 7 | B20: =Harvest_Schedule!$B$28 | C20: =Harvest_Schedule!$C$28 | D20: =Stumpage*(1+PriceGrowth)^$A20 | E20: =$B20*$D20 | F20: =IF(AND(CarbonOn,$A20>0),Area_ha*CarbonArea*CarbonRate*CarbonPrice,0) | G20: =-$C20*RegenCost | H20: =IF($A20>0,-Area_ha*MgmtCost,0) | I20: =IF($A20=0,-PurchasePrice*(1+AcqCostPct),0) | J20: =IF($A20=HoldYears,TerminalValue,0) | K20: =SUM($E20:$J20) | L20: =1/(1+DiscRate)^$A20 | M20: =$K20*$L20 | N20: =SUM($M$13:$M20)
A21: 8 | B21: =Harvest_Schedule!$B$29 | C21: =Harvest_Schedule!$C$29 | D21: =Stumpage*(1+PriceGrowth)^$A21 | E21: =$B21*$D21 | F21: =IF(AND(CarbonOn,$A21>0),Area_ha*CarbonArea*CarbonRate*CarbonPrice,0) | G21: =-$C21*RegenCost | H21: =IF($A21>0,-Area_ha*MgmtCost,0) | I21: =IF($A21=0,-PurchasePrice*(1+AcqCostPct),0) | J21: =IF($A21=HoldYears,TerminalValue,0) | K21: =SUM($E21:$J21) | L21: =1/(1+DiscRate)^$A21 | M21: =$K21*$L21 | N21: =SUM($M$13:$M21)
A22: 9 | B22: =Harvest_Schedule!$B$30 | C22: =Harvest_Schedule!$C$30 | D22: =Stumpage*(1+PriceGrowth)^$A22 | E22: =$B22*$D22 | F22: =IF(AND(CarbonOn,$A22>0),Area_ha*CarbonArea*CarbonRate*CarbonPrice,0) | G22: =-$C22*RegenCost | H22: =IF($A22>0,-Area_ha*MgmtCost,0) | I22: =IF($A22=0,-PurchasePrice*(1+AcqCostPct),0) | J22: =IF($A22=HoldYears,TerminalValue,0) | K22: =SUM($E22:$J22) | L22: =1/(1+DiscRate)^$A22 | M22: =$K22*$L22 | N22: =SUM($M$13:$M22)
A23: 10 | B23: =Harvest_Schedule!$B$31 | C23: =Harvest_Schedule!$C$31 | D23: =Stumpage*(1+PriceGrowth)^$A23 | E23: =$B23*$D23 | F23: =IF(AND(CarbonOn,$A23>0),Area_ha*CarbonArea*CarbonRate*CarbonPrice,0) | G23: =-$C23*RegenCost | H23: =IF($A23>0,-Area_ha*MgmtCost,0) | I23: =IF($A23=0,-PurchasePrice*(1+AcqCostPct),0) | J23: =IF($A23=HoldYears,TerminalValue,0) | K23: =SUM($E23:$J23) | L23: =1/(1+DiscRate)^$A23 | M23: =$K23*$L23 | N23: =SUM($M$13:$M23)
A24: 11 | B24: =Harvest_Schedule!$B$32 | C24: =Harvest_Schedule!$C$32 | D24: =Stumpage*(1+PriceGrowth)^$A24 | E24: =$B24*$D24 | F24: =IF(AND(CarbonOn,$A24>0),Area_ha*CarbonArea*CarbonRate*CarbonPrice,0) | G24: =-$C24*RegenCost | H24: =IF($A24>0,-Area_ha*MgmtCost,0) | I24: =IF($A24=0,-PurchasePrice*(1+AcqCostPct),0) | J24: =IF($A24=HoldYears,TerminalValue,0) | K24: =SUM($E24:$J24) | L24: =1/(1+DiscRate)^$A24 | M24: =$K24*$L24 | N24: =SUM($M$13:$M24)
A25: 12 | B25: =Harvest_Schedule!$B$33 | C25: =Harvest_Schedule!$C$33 | D25: =Stumpage*(1+PriceGrowth)^$A25 | E25: =$B25*$D25 | F25: =IF(AND(CarbonOn,$A25>0),Area_ha*CarbonArea*CarbonRate*CarbonPrice,0) | G25: =-$C25*RegenCost | H25: =IF($A25>0,-Area_ha*MgmtCost,0) | I25: =IF($A25=0,-PurchasePrice*(1+AcqCostPct),0) | J25: =IF($A25=HoldYears,TerminalValue,0) | K25: =SUM($E25:$J25) | L25: =1/(1+DiscRate)^$A25 | M25: =$K25*$L25 | N25: =SUM($M$13:$M25)
A26: 13 | B26: =Harvest_Schedule!$B$34 | C26: =Harvest_Schedule!$C$34 | D26: =Stumpage*(1+PriceGrowth)^$A26 | E26: =$B26*$D26 | F26: =IF(AND(CarbonOn,$A26>0),Area_ha*CarbonArea*CarbonRate*CarbonPrice,0) | G26: =-$C26*RegenCost | H26: =IF($A26>0,-Area_ha*MgmtCost,0) | I26: =IF($A26=0,-PurchasePrice*(1+AcqCostPct),0) | J26: =IF($A26=HoldYears,TerminalValue,0) | K26: =SUM($E26:$J26) | L26: =1/(1+DiscRate)^$A26 | M26: =$K26*$L26 | N26: =SUM($M$13:$M26)
A27: 14 | B27: =Harvest_Schedule!$B$35 | C27: =Harvest_Schedule!$C$35 | D27: =Stumpage*(1+PriceGrowth)^$A27 | E27: =$B27*$D27 | F27: =IF(AND(CarbonOn,$A27>0),Area_ha*CarbonArea*CarbonRate*CarbonPrice,0) | G27: =-$C27*RegenCost | H27: =IF($A27>0,-Area_ha*MgmtCost,0) | I27: =IF($A27=0,-PurchasePrice*(1+AcqCostPct),0) | J27: =IF($A27=HoldYears,TerminalValue,0) | K27: =SUM($E27:$J27) | L27: =1/(1+DiscRate)^$A27 | M27: =$K27*$L27 | N27: =SUM($M$13:$M27)
A28: 15 | B28: =Harvest_Schedule!$B$36 | C28: =Harvest_Schedule!$C$36 | D28: =Stumpage*(1+PriceGrowth)^$A28 | E28: =$B28*$D28 | F28: =IF(AND(CarbonOn,$A28>0),Area_ha*CarbonArea*CarbonRate*CarbonPrice,0) | G28: =-$C28*RegenCost | H28: =IF($A28>0,-Area_ha*MgmtCost,0) | I28: =IF($A28=0,-PurchasePrice*(1+AcqCostPct),0) | J28: =IF($A28=HoldYears,TerminalValue,0) | K28: =SUM($E28:$J28) | L28: =1/(1+DiscRate)^$A28 | M28: =$K28*$L28 | N28: =SUM($M$13:$M28)
A29: 16 | B29: =Harvest_Schedule!$B$37 | C29: =Harvest_Schedule!$C$37 | D29: =Stumpage*(1+PriceGrowth)^$A29 | E29: =$B29*$D29 | F29: =IF(AND(CarbonOn,$A29>0),Area_ha*CarbonArea*CarbonRate*CarbonPrice,0) | G29: =-$C29*RegenCost | H29: =IF($A29>0,-Area_ha*MgmtCost,0) | I29: =IF($A29=0,-PurchasePrice*(1+AcqCostPct),0) | J29: =IF($A29=HoldYears,TerminalValue,0) | K29: =SUM($E29:$J29) | L29: =1/(1+DiscRate)^$A29 | M29: =$K29*$L29 | N29: =SUM($M$13:$M29)
A30: 17 | B30: =Harvest_Schedule!$B$38 | C30: =Harvest_Schedule!$C$38 | D30: =Stumpage*(1+PriceGrowth)^$A30 | E30: =$B30*$D30 | F30: =IF(AND(CarbonOn,$A30>0),Area_ha*CarbonArea*CarbonRate*CarbonPrice,0) | G30: =-$C30*RegenCost | H30: =IF($A30>0,-Area_ha*MgmtCost,0) | I30: =IF($A30=0,-PurchasePrice*(1+AcqCostPct),0) | J30: =IF($A30=HoldYears,TerminalValue,0) | K30: =SUM($E30:$J30) | L30: =1/(1+DiscRate)^$A30 | M30: =$K30*$L30 | N30: =SUM($M$13:$M30)
A31: 18 | B31: =Harvest_Schedule!$B$39 | C31: =Harvest_Schedule!$C$39 | D31: =Stumpage*(1+PriceGrowth)^$A31 | E31: =$B31*$D31 | F31: =IF(AND(CarbonOn,$A31>0),Area_ha*CarbonArea*CarbonRate*CarbonPrice,0) | G31: =-$C31*RegenCost | H31: =IF($A31>0,-Area_ha*MgmtCost,0) | I31: =IF($A31=0,-PurchasePrice*(1+AcqCostPct),0) | J31: =IF($A31=HoldYears,TerminalValue,0) | K31: =SUM($E31:$J31) | L31: =1/(1+DiscRate)^$A31 | M31: =$K31*$L31 | N31: =SUM($M$13:$M31)
A32: 19 | B32: =Harvest_Schedule!$B$40 | C32: =Harvest_Schedule!$C$40 | D32: =Stumpage*(1+PriceGrowth)^$A32 | E32: =$B32*$D32 | F32: =IF(AND(CarbonOn,$A32>0),Area_ha*CarbonArea*CarbonRate*CarbonPrice,0) | G32: =-$C32*RegenCost | H32: =IF($A32>0,-Area_ha*MgmtCost,0) | I32: =IF($A32=0,-PurchasePrice*(1+AcqCostPct),0) | J32: =IF($A32=HoldYears,TerminalValue,0) | K32: =SUM($E32:$J32) | L32: =1/(1+DiscRate)^$A32 | M32: =$K32*$L32 | N32: =SUM($M$13:$M32)
A33: 20 | B33: =Harvest_Schedule!$B$41 | C33: =Harvest_Schedule!$C$41 | D33: =Stumpage*(1+PriceGrowth)^$A33 | E33: =$B33*$D33 | F33: =IF(AND(CarbonOn,$A33>0),Area_ha*CarbonArea*CarbonRate*CarbonPrice,0) | G33: =-$C33*RegenCost | H33: =IF($A33>0,-Area_ha*MgmtCost,0) | I33: =IF($A33=0,-PurchasePrice*(1+AcqCostPct),0) | J33: =IF($A33=HoldYears,TerminalValue,0) | K33: =SUM($E33:$J33) | L33: =1/(1+DiscRate)^$A33 | M33: =$K33*$L33 | N33: =SUM($M$13:$M33)
A34: 21 | B34: =Harvest_Schedule!$B$42 | C34: =Harvest_Schedule!$C$42 | D34: =Stumpage*(1+PriceGrowth)^$A34 | E34: =$B34*$D34 | F34: =IF(AND(CarbonOn,$A34>0),Area_ha*CarbonArea*CarbonRate*CarbonPrice,0) | G34: =-$C34*RegenCost | H34: =IF($A34>0,-Area_ha*MgmtCost,0) | I34: =IF($A34=0,-PurchasePrice*(1+AcqCostPct),0) | J34: =IF($A34=HoldYears,TerminalValue,0) | K34: =SUM($E34:$J34) | L34: =1/(1+DiscRate)^$A34 | M34: =$K34*$L34 | N34: =SUM($M$13:$M34)
A35: 22 | B35: =Harvest_Schedule!$B$43 | C35: =Harvest_Schedule!$C$43 | D35: =Stumpage*(1+PriceGrowth)^$A35 | E35: =$B35*$D35 | F35: =IF(AND(CarbonOn,$A35>0),Area_ha*CarbonArea*CarbonRate*CarbonPrice,0) | G35: =-$C35*RegenCost | H35: =IF($A35>0,-Area_ha*MgmtCost,0) | I35: =IF($A35=0,-PurchasePrice*(1+AcqCostPct),0) | J35: =IF($A35=HoldYears,TerminalValue,0) | K35: =SUM($E35:$J35) | L35: =1/(1+DiscRate)^$A35 | M35: =$K35*$L35 | N35: =SUM($M$13:$M35)
A36: 23 | B36: =Harvest_Schedule!$B$44 | C36: =Harvest_Schedule!$C$44 | D36: =Stumpage*(1+PriceGrowth)^$A36 | E36: =$B36*$D36 | F36: =IF(AND(CarbonOn,$A36>0),Area_ha*CarbonArea*CarbonRate*CarbonPrice,0) | G36: =-$C36*RegenCost | H36: =IF($A36>0,-Area_ha*MgmtCost,0) | I36: =IF($A36=0,-PurchasePrice*(1+AcqCostPct),0) | J36: =IF($A36=HoldYears,TerminalValue,0) | K36: =SUM($E36:$J36) | L36: =1/(1+DiscRate)^$A36 | M36: =$K36*$L36 | N36: =SUM($M$13:$M36)
A37: 24 | B37: =Harvest_Schedule!$B$45 | C37: =Harvest_Schedule!$C$45 | D37: =Stumpage*(1+PriceGrowth)^$A37 | E37: =$B37*$D37 | F37: =IF(AND(CarbonOn,$A37>0),Area_ha*CarbonArea*CarbonRate*CarbonPrice,0) | G37: =-$C37*RegenCost | H37: =IF($A37>0,-Area_ha*MgmtCost,0) | I37: =IF($A37=0,-PurchasePrice*(1+AcqCostPct),0) | J37: =IF($A37=HoldYears,TerminalValue,0) | K37: =SUM($E37:$J37) | L37: =1/(1+DiscRate)^$A37 | M37: =$K37*$L37 | N37: =SUM($M$13:$M37)
A38: 25 | B38: =Harvest_Schedule!$B$46 | C38: =Harvest_Schedule!$C$46 | D38: =Stumpage*(1+PriceGrowth)^$A38 | E38: =$B38*$D38 | F38: =IF(AND(CarbonOn,$A38>0),Area_ha*CarbonArea*CarbonRate*CarbonPrice,0) | G38: =-$C38*RegenCost | H38: =IF($A38>0,-Area_ha*MgmtCost,0) | I38: =IF($A38=0,-PurchasePrice*(1+AcqCostPct),0) | J38: =IF($A38=HoldYears,TerminalValue,0) | K38: =SUM($E38:$J38) | L38: =1/(1+DiscRate)^$A38 | M38: =$K38*$L38 | N38: =SUM($M$13:$M38)
A39: 26 | B39: =Harvest_Schedule!$B$47 | C39: =Harvest_Schedule!$C$47 | D39: =Stumpage*(1+PriceGrowth)^$A39 | E39: =$B39*$D39 | F39: =IF(AND(CarbonOn,$A39>0),Area_ha*CarbonArea*CarbonRate*CarbonPrice,0) | G39: =-$C39*RegenCost | H39: =IF($A39>0,-Area_ha*MgmtCost,0) | I39: =IF($A39=0,-PurchasePrice*(1+AcqCostPct),0) | J39: =IF($A39=HoldYears,TerminalValue,0) | K39: =SUM($E39:$J39) | L39: =1/(1+DiscRate)^$A39 | M39: =$K39*$L39 | N39: =SUM($M$13:$M39)
A40: 27 | B40: =Harvest_Schedule!$B$48 | C40: =Harvest_Schedule!$C$48 | D40: =Stumpage*(1+PriceGrowth)^$A40 | E40: =$B40*$D40 | F40: =IF(AND(CarbonOn,$A40>0),Area_ha*CarbonArea*CarbonRate*CarbonPrice,0) | G40: =-$C40*RegenCost | H40: =IF($A40>0,-Area_ha*MgmtCost,0) | I40: =IF($A40=0,-PurchasePrice*(1+AcqCostPct),0) | J40: =IF($A40=HoldYears,TerminalValue,0) | K40: =SUM($E40:$J40) | L40: =1/(1+DiscRate)^$A40 | M40: =$K40*$L40 | N40: =SUM($M$13:$M40)
A41: 28 | B41: =Harvest_Schedule!$B$49 | C41: =Harvest_Schedule!$C$49 | D41: =Stumpage*(1+PriceGrowth)^$A41 | E41: =$B41*$D41 | F41: =IF(AND(CarbonOn,$A41>0),Area_ha*CarbonArea*CarbonRate*CarbonPrice,0) | G41: =-$C41*RegenCost | H41: =IF($A41>0,-Area_ha*MgmtCost,0) | I41: =IF($A41=0,-PurchasePrice*(1+AcqCostPct),0) | J41: =IF($A41=HoldYears,TerminalValue,0) | K41: =SUM($E41:$J41) | L41: =1/(1+DiscRate)^$A41 | M41: =$K41*$L41 | N41: =SUM($M$13:$M41)
A42: 29 | B42: =Harvest_Schedule!$B$50 | C42: =Harvest_Schedule!$C$50 | D42: =Stumpage*(1+PriceGrowth)^$A42 | E42: =$B42*$D42 | F42: =IF(AND(CarbonOn,$A42>0),Area_ha*CarbonArea*CarbonRate*CarbonPrice,0) | G42: =-$C42*RegenCost | H42: =IF($A42>0,-Area_ha*MgmtCost,0) | I42: =IF($A42=0,-PurchasePrice*(1+AcqCostPct),0) | J42: =IF($A42=HoldYears,TerminalValue,0) | K42: =SUM($E42:$J42) | L42: =1/(1+DiscRate)^$A42 | M42: =$K42*$L42 | N42: =SUM($M$13:$M42)
...

Sheet Sensitivity
A1: Two-way sensitivity
A2: Project IRR. Values are computed in Python because each cell is a complete model re-run, including re-solving the rotation and the harvest schedule.
A3: HYPOTHETICAL TRACT, FOR PORTFOLIO PURPOSES ONLY. NOT INVESTMENT ADVICE.
A5: IRR by net stumpage price and real discount rate
A6: The discount rate barely moves the IRR: it enters only through the rotation age and the price of the year-30 exit, not through the operating cash flows.
A7: Net stumpage ($/m³) ↓ / Real discount rate → | B7: 4% | C7: 5% | D7: 6% | E7: 7% | F7: 8%
A8: $34 | B8: 0.045276621 | C8: 0.044170276 | D8: 0.043453809 | E8: 0.043079755 | F8: 0.042906205
A9: $38 | B9: 0.05579598 | C9: 0.055028383 | D9: 0.054798835 | E9: 0.054612986 | F9: 0.054377934
A10: $43 | B10: 0.065649078 | C10: 0.065541426 | D10: 0.065264253 | E10: 0.065268386 | F10: 0.065425546
A11: $48 | B11: 0.075423057 | C11: 0.075282877 | D11: 0.075212966 | E11: 0.075398045 | F11: 0.075716205
A12: $53 | B12: 0.084474007 | C12: 0.084638575 | D12: 0.085205211 | E12: 0.085541632 | F12: 0.085599005
A13: $58 | B13: 0.093235198 | C13: 0.093696387 | D13: 0.094518131 | E13: 0.095019089 | F13: 0.095165141
A14: $62 | B14: 0.101771 | C14: 0.10252149 | D14: 0.10359103 | E14: 0.10425089 | F14: 0.10497672
A17: IRR by purchase price and real stumpage price growth
A18: Entry price is the dominant variable. Bold cells clear the hurdle.
A19: Purchase price ↓ / Real price growth → | B19: -0.5% | C19: +0.0% | D19: +0.5% | E19: +1.0% | F19: +1.5%
A20: $64M | B20: 0.10055863 | C20: 0.10649297 | D20: 0.11239075 | E20: 0.11825672 | F20: 0.12409487
A21: $78M | B21: 0.079342462 | C21: 0.085188949 | D21: 0.090993577 | E21: 0.096762027 | F21: 0.10249907
A22: $92M | B22: 0.063691775 | C22: 0.069475415 | D22: 0.075212966 | E22: 0.08091088 | F22: 0.08657455
A23: $106M | B23: 0.051480562 | C23: 0.057216105 | D23: 0.062902123 | E23: 0.068545703 | F23: 0.074152747
A24: $120M | B24: 0.04156766 | C24: 0.047264621 | D24: 0.052909212 | E24: 0.058509051 | F24: 0.064070466
A26: Hurdle rate for shading and bolding: 6.0%

Sheet Monte_Carlo
A1: Monte Carlo risk analysis
A2: 10,000 paths, seed 42. Mean-reverting stumpage prices and random wildfire or pest losses, run through the same cohort model.
A3: HYPOTHETICAL TRACT, FOR PORTFOLIO PURPOSES ONLY. NOT INVESTMENT ADVICE.
A5: IRR distribution by strategy
A6: Strategy | B6: P5 | C6: P25 | D6: Median | E6: P75 | F6: P95 | G6: Mean | H6: P(IRR < hurdle)
A7: Scheduled harvest | B7: 0.055804913 | C7: 0.068063473 | D7: 0.077385839 | E7: 0.088194066 | F7: 0.10551651 | G7: 0.078698911 | H7: 0.0956
A8: Flexible harvest | B8: 0.053742074 | C8: 0.06811037 | D8: 0.080154145 | E8: 0.095032018 | F8: 0.11808503 | G8: 0.082419847 | H8: 0.1156
A10: Headline risk measures
A11: Hurdle rate | B11: =Hurdle | C11: Linked from Assumptions
A12: Probability of missing the hurdle (scheduled) | B12: 0.0956 | C12: Share of the 10,000 paths returning less than the hurdle
A13: Value of harvest timing flexibility | B13: 3526108 | C13: Mean NPV of the flexible strategy less the scheduled strategy
A14: Value of flexibility per hectare | B14: 176.3054 | C14: The real option is worth this much per hectare
A15: Flexibility gain in mean IRR | B15: 0.0037209359 | C15: Same comparison, expressed as a return
A16: Expected cost of fire and pests | B16: 1124144.4 | C16: Mean NPV with disturbances switched off, less the base case, on identical price paths
A17: Expected cost per hectare | B17: 56.207222
A18: Mean disturbance events per path | B18: 0.5971 | C18: 30 years at the configured annual probability
A19: Paths seeing at least one event | B19: 0.4551
A20: Worst single event in the simulation | B20: 0.32643909 | C20: Share of the tract destroyed in one year
A23: Why flexibility has value
A24: Prices mean revert, so a low price today is information: it is likely to rise. The even-flow agreement still allows the cut to move ±15% around the target, and shifting volume out of weak years into strong ones is worth the figure above. Under a random walk the same option would be worth nothing, because today's price would already be the best forecast of tomorrow's.

Sheet Market_Analysis
A1: Portfolio fit: correlation and inflation
A2: Real market data. This sheet tests the two claims usually made for timberland and reports what the data says, including where it disagrees.
A3: HYPOTHETICAL TRACT, FOR PORTFOLIO PURPOSES ONLY. NOT INVESTMENT ADVICE.
A5: Correlation of monthly total returns
A6: Feb 1985 to Sep 2026. High correlation is shaded orange because it is the unhelpful outcome for a diversification case.
B7: Weyerhaeuser (WY) | C7: Rayonier (RYN) | D7: Acadian Timber (ADN) | E7: Gladstone Land (LAND) | F7: Farmland Partners (FPI) | G7: S&P/TSX Composite | H7: S&P 500 | I7: Canadian bonds (XBB)
A8: Weyerhaeuser (WY) | B8: 1 | C8: 0.68183786 | D8: 0.50831225 | E8: 0.40700068 | F8: 0.35295607 | G8: 0.55145253 | H8: 0.67257603 | I8: 0.10102881
A9: Rayonier (RYN) | B9: 0.68183786 | C9: 1 | D9: 0.41751886 | E9: 0.33479066 | F9: 0.42283864 | G9: 0.46103915 | H9: 0.53911011 | I9: 0.11535389
A10: Acadian Timber (ADN) | B10: 0.50831225 | C10: 0.41751886 | D10: 1 | E10: 0.21334601 | F10: 0.22834952 | G10: 0.40892041 | H10: 0.40974119 | I10: 0.093516665
A11: Gladstone Land (LAND) | B11: 0.40700068 | C11: 0.33479066 | D11: 0.21334601 | E11: 1 | F11: 0.44170968 | G11: 0.41608983 | H11: 0.42665493 | I11: 0.2405179
A12: Farmland Partners (FPI) | B12: 0.35295607 | C12: 0.42283864 | D12: 0.22834952 | E12: 0.44170968 | F12: 1 | G12: 0.34283081 | H12: 0.35181405 | I12: 0.13743142
A13: S&P/TSX Composite | B13: 0.55145253 | C13: 0.46103915 | D13: 0.40892041 | E13: 0.41608983 | F13: 0.34283081 | G13: 1 | H13: 0.78244772 | I13: 0.16420296
A14: S&P 500 | B14: 0.67257603 | C14: 0.53911011 | D14: 0.40974119 | E14: 0.42665493 | F14: 0.35181405 | G14: 0.78244772 | H14: 1 | I14: 0.11815756
A15: Canadian bonds (XBB) | B15: 0.10102881 | C15: 0.11535389 | D15: 0.093516665 | E15: 0.2405179 | F15: 0.13743142 | G15: 0.16420296 | H15: 0.11815756 | I15: 1
A18: Inflation beta: annual total return regressed on annual CPI inflation
A19: CPI source: Statistics Canada table 18-10-0004-01, Consumer Price Index, all-items, Canada, monthly (vector v41690973)
A20: Asset | B20: Inflation beta | C20: Standard error | D20: t-statistic | E20: p-value | F20: R² | G20: Years
A21: Weyerhaeuser (WY) | B21: -1.3279488 | C21: 2.6717785 | D21: -0.49702803 | E21: 0.62195974 | F21: 0.006294408 | G21: 41
A22: Rayonier (RYN) | B22: -1.4531071 | C22: 3.3524395 | D22: -0.43344767 | E22: 0.66779045 | F22: 0.0062235872 | G22: 32
A23: Acadian Timber (ADN) | B23: -2.7148678 | C23: 3.521586 | D23: -0.7709219 | E23: 0.45198814 | F23: 0.035814698 | G23: 18
A24: Gladstone Land (LAND) | B24: 3.8704776 | C24: 8.909439 | D24: 0.43442439 | E24: 0.67237914 | F24: 0.016867387 | G24: 13
A25: Farmland Partners (FPI) | B25: 2.1662308 | C25: 5.3275842 | D25: 0.40660658 | E25: 0.69286265 | F25: 0.016264 | G25: 12
A26: S&P/TSX Composite | B26: -0.3529171 | C26: 1.7040291 | D26: -0.20710744 | E26: 0.83700355 | F26: 0.0010986248 | G26: 41
A27: S&P 500 | B27: -1.3223924 | C27: 1.8589232 | D27: -0.71137549 | E27: 0.48108507 | F27: 0.012809557 | G27: 41
A28: Canadian bonds (XBB) | B28: -1.9698913 | C28: 0.61172911 | D28: -3.220202 | E28: 0.0036572176 | F28: 0.30171053 | G28: 26
A31: Average annual return in high versus low inflation years
A32: Split at the median annual inflation rate of 2.13% (21 high years, 20 low years).
A33: Asset | B33: High inflation years | C33: Low inflation years | D33: Difference
A34: Weyerhaeuser (WY) | B34: 0.10032853 | C34: 0.074157678 | D34: 0.026170853
A35: Rayonier (RYN) | B35: 0.10640118 | C35: 0.10223088 | D35: 0.0041703028
A36: Acadian Timber (ADN) | B36: 0.16749949 | C36: 0.12095702 | D36: 0.046542475
A37: Gladstone Land (LAND) | B37: 0.14869751 | C37: -0.0016766881 | D37: 0.1503742
A38: Farmland Partners (FPI) | B38: 0.17095627 | C38: -0.013971611 | D38: 0.18492788
A39: S&P/TSX Composite | B39: 0.081223114 | C39: 0.066284142 | D39: 0.014938972
A40: S&P 500 | B40: 0.095994018 | C40: 0.11409324 | D40: -0.018099221
A41: Canadian bonds (XBB) | B41: 0.031949455 | C41: 0.04025916 | D41: -0.0083097055
A43: Limitation that qualifies everything on this sheet
A44: Listed timber and farmland REITs are imperfect proxies for private timberland. They are equities first: they carry market beta, leverage and daily sentiment that a directly held tract does not, so the correlations measured here are an upper bound and understate the diversification a private portfolio would deliver. Appraisal-based private indices have the opposite problem: smoothing suppresses measured correlation and volatility. The truth sits between the two, and neither is available for a 20,000 ha Alberta tract specifically.
